Workbook
Name _ftn1: 'M&V Budget'!#REF!
Name _ftnref1: 'M&V Budget'!#REF!

Sheet Introduction
A1: MEASUREMENT AND VERIFICATION - M&V PLANNING TOOL
A2: THIS TOOL
A3: This M&V planning tool has been developed to assist M&V planners capture and incorporate the various M&V design elements. The template is presented in a spreadsheet for ease of calculations, with the following contents:
A5: Worksheet Tab | B5: Purpose
A6: M&V Planning Process | B6: Describe the M&V process and corresponding use of this tool
A7: ECM Project Background | B7: To capture details for the site and ECM, including the estimated project benefits, implementation plan and key stakeholders
A8: M&V Requirements | B8: To capture the M&V requirements key considerations, desired outcomes and success criteria, as well as the M&V project details.
A9: M&V Design | B9: To capture the essential elements of the M&V Plan. This includes preferred M&V Option, measurement boundary definition, details of key parameters, and process information relating to conducting measurements, calculating saving and uncertainty.
A10: M&V Budget | B10: To prepare a project budget, based on the tasks, resources, equipment and other needs. The final figure is measured against the ECM project costs and savings as a sanity check.
A11: M&V Tasks | B11: To capture the step-by-step list of tasks, and allocation of resources
A12: M&V Timing | B12: A Gantt Chart based timeline, where tasks are given a start and completion date, so that the overall project timeline can be developed.
A15: M&V OPERATIONAL GUIDE
A16: Your Guide to successful M&V projects
A17: The Measurement and Verification (M&V) Operational Guide has been developed to help M&V practitioners, business energy savings project managers, government energy efficiency program managers and policy makers translate M&V theory into successful M&V projects.
A18: By following this guide you will be implementing the International Performance Measurement and Verification Protocol (IPMVP) a typical M&V process. Practical tips, tools and scenario examples are provided to assist with decision making, planning, measuring, analysing and reporting outcomes.
A20: But what is M&V exactly?
A22: M&V is the process of using measurement to reliably determine actual savings for energy, demand, cost and greenhouse gases within a site by an Energy Conservation Measure (ECM). Measurements are used to verify savings, rather than applying deemed savings or theoretical engineering calculations, which are based on previous studies, manufacturer-provided information or other indirect data. Savings are determined by comparing post-retrofit performance against a ‘business as usual’ forecast.
A23: Across Australia the use of M&V has been growing, driven by business and as a requirement in government funding and financing programs. M&V enables:
A24: - calculation of savings for projects that have high uncertainty or highly variable characteristics
A25: - verification of installed performance against manufacturer claims
A26: - a verified result which can be stated with confidence and can prove return on investment
A27: - demonstration of performance where a financial incentive or penalty is involved
A28: - effective management of energy costs
... A80: © Copyright State of NSW and Office of Environment and Heritage With the exception of photographs, the State of NSW and Office of Environment and Heritage are pleased to allow this material to be reproduced in whole or in part for educational and non-commercial use, provided the meaning is unchanged and its source, publisher and authorship are acknowledged. Specific permission is required for the reproduction of photographs. The Office of Environment and Heritage (OEH) has compiled this guideline in good faith, exercising all due care and attention. No representation is made about the accuracy, completeness or suitability of the information in this publication for any particular purpose. OEH shall not be liable for any damage which may occur to any person or organisation taking action or not on the basis of this publication. Readers should seek appropriate advice when applying the information to their specific needs. Every effort has been made to ensure that the information in this document is accurate at the time of publication. However, as appropriate, readers should obtain independent advice before making any decision based on this information. Published by: Office of Environment and Heritage NSW 59 Goulburn Street, Sydney NSW 2000 PO Box A290, Sydney South NSW 1232 Phone: (02) 9995 5000 (switchboard) Phone: 131 555 (environment information and publications requests) Phone: 1300 361 967 (national parks, climate change and energy efficiency information, and publications requests) Fax: (02) 9995 5999 TTY: (02) 9211 4723 Email: info@environment.nsw.gov.au Website: www.environment.nsw.gov.au Report pollution and environmental incidents Environment Line: 131 555 (NSW only) or info@environment.nsw.gov.au See also www.environment.nsw.gov.au OEH 2012/0999 December 2012

Sheet M&V Planning Process
A1: MEASUREMENT AND VERIFICATION - PLANNING PROCESS
A2: INTRODUCTION
A3: The suggested M&V planning process listed below can be used as a basis for developing a M&V plan. A full description of this process is provided in the M&V Operational Guide: Planning Guide.
A4: PLANNING PROCESS | B4: PLANNING TOOL REFERENCE
A5: Process Step | B5: ECM Project Background | C5: M&V Requirements | D5: M&V Plan | E5: M&V Budget | F5: M&V Tasks | G5: M&V Timing
B6: Enter the details of key stakeholders | C6: Capture the M&V requirements key considerations, desired outcomes and success criteria, as well as the M&V project details. | D6: Enter the details of the M&V project manager and project team. | E6: Enter the names of resources who will be conducting tasks within the M&V project
B7: Enter the details of the site and ECM, including implementation dates, milestones and potential issues
C8: Enter the details of the M&V requirements and desired outcomes. This includes the project scope and objective, considerations, risks, deliverables, and measures of success.
C9: Enter the preliminary budget figure.
D10: Enter the details of design and planning decisions, including notes and assumptions
D11: Enter details of the equipment requirements, proposed techniques for collecting and manipulating data, and for calculating savings. | E11: List the equipment/software/external expertise that has to be procured.
F12: Document the step-by-step list of tasks in order, allocating resources and budget time allocation. | G12: Starting with the ECM implementation date, determine the start and end dates for each task.
E13: Finalise the budget by completing cost elements for labour, equipment and other expenses.
C14: Review the requirements within this tab, against the M&V design presented in the Plan, Budget and Timing tabs.
B15: The completed workbook contains the M&V planning elements. Contents may be transferred into proposals or presentations if required to assist with business case approval.

Sheet ECM Project Background
A1: ENERGY CONSERVATION MEASURE - PROJECT BACKGROUND
A2: SITE DETAILS
A3: Site Name
A4: Address
A5: Site Overview
A6: DESCRIPTION OF THE ECM PROJECT(S) BEING IMPLEMENTED
A7: Description of ECM Project being implemented
A8: Estimated Project Benefits | B8: Energy (GJ) | C8: Cost ($) | D8: Greenhouse (t. CO2-e)
B9: 0 | C9: 0 | D9: 0
A10: Estimated Implementation Cost ($) | B10: 0
A11: Implementation Plan Description
A12: Key Dates
A13: Key Stakeholders/Contacts | B13: Name / Company | C13: Role | D13: Contact

Sheet M&V Requirements
A1: MEASUREMENT AND VERIFICATION - PROJECT SUMMARY AND REQUIREMENTS
A2: PROJECT INFORMATION
A3: Project Name | C3: Project #
A4: Project manager | C4: Last Updated
A5: Project Team | B5: Name / Company | C5: Role | D5: Contact
B6: [Resource 1]
B7: [Resource 2]
B8: [Resource 3]
B9: [Resource 4]
B10: [Resource 5]
B11: [Resource 6]
A12: Preliminary Budget
A15: SUMMARY
A16: Objectives
A17: Scope | B17: In Scope | C17: Out of Scope
A21: Deliverables | B21: Deliverable | C21: Due Date
A25: Key considerations | B25: Assumptions & Constraints | C25: Risks
C26: Category | D26: Risk Description
A34: Success criteria | B34: 1 -
B35: 2 -
B36: 3 -
B37: 4 -
B38: 5 -

Sheet M&V Design
A1: MEASUREMENT AND VERIFICATION - M&V DESIGN
A2: PROJECT INFORMATION
A3: Project Name | B3: ='M&V Requirements'!B3 -> 0 | C3: Project # | D3: ='M&V Requirements'!D3 -> 0
A4: Project manager | B4: ='M&V Requirements'!B4 -> 0 | C4: Last Updated | D4: ='M&V Requirements'!D4 -> 0
A7: M&V APPROACH
A8: M&V Option Selected
A9: Desired Accuracy (%)
A10: Overall Approach
A11: Baseline Period
A12: Post-Retrofit Period
A13: MEASUREMENT BOUNDARY
A14: Description of Measurement Boundary
A15: Linked documents or drawings
A16: KEY PARAMETERS AND VARIABLES
A17: Key Parameters to be measured | B17: Parameter | C17: Measurement period and duration | D17: Method for Collecting Data
A21: Other Parameters to consider | B21: Parameter | C21: Reason for consideration | D21: Method for Considering/Estimating Data
A25: Baseline Adjustments and Independent Variables that affect Energy Use within Boundary | B25: Type of Adjustment/Variable | C25: Routine/Non Routine | D25: Method for Adjusting baseline
A28: Potential interactive effects identified | B28: Interactive Effect | C28: Materiality | D28: Agreed Approach
A31: EQUIPMENT REQUIREMENTS
A32: Measurement Equipment | B32: Equipment | C32: To be sourced from (who/when/how) | D32: Period required
A36: CALCULATING RESULTS
A37: Approach/method for calculating energy and demand savings
A38: Approach/method for calculating savings uncertainty
A39: Approach for calculating cost savings and greenhouse gas emissions
A40: Approach for extrapolating results

Sheet M&V Budget
A1: MEASUREMENT AND VERIFICATION - BUDGET PLANNER
A2: PROJECT INFORMATION
A3: Project Name | B3: ='M&V Design'!B3 -> 0 | D3: Project # | E3: ='M&V Design'!D3 -> 0
A4: Project manager | B4: ='M&V Design'!B4 -> 0 | D4: Last Updated | E4: ='M&V Design'!D4 -> 0
A7: BUDGET DETAILS
A8: Internal Expenses
A9: Resource (insert name/role) | B9: Hourly Rate | C9: # Hours | D9: Total Cost | F9: Notes/Comments
A10: ='M&V Requirements'!B6 -> [Resource 1] | B10: 140 | C10: ='M&V Tasks'!C8 -> 1 | D10: =SUM(B10*C10) -> 140
A11: ='M&V Requirements'!B7 -> [Resource 2] | B11: 120 | C11: ='M&V Tasks'!D8 -> 0 | D11: =SUM(B11*C11) -> 0
A12: ='M&V Requirements'!B8 -> [Resource 3] | B12: 80 | C12: ='M&V Tasks'!E8 -> 0 | D12: =SUM(B12*C12) -> 0
A13: ='M&V Requirements'!B9 -> [Resource 4] | B13: 90 | C13: ='M&V Tasks'!F8 -> 0 | D13: =SUM(B13*C13) -> 0
A14: ='M&V Requirements'!B10 -> [Resource 5] | B14: 80 | C14: ='M&V Tasks'!G8 -> 0 | D14: =SUM(B14*C14) -> 0
A15: ='M&V Requirements'!B11 -> [Resource 6] | B15: 80 | C15: ='M&V Tasks'!H8 -> 0 | D15: =SUM(B15*C15) -> 0
A16: Other Internal Expenses | D16: Total Cost
A17: Enter expense type | D17: 0
A18: Enter expense type | D18: 0
A19: Enter expense type | D19: 0
A20: Total Internal Expenses | E20: =SUM(D9:D19) -> 140
A21: External Expenses
A22: External Labour Costs (Consultants, Contractors) | D22: Total Cost
A23: Enter external labour cost item | D23: 0
A24: Enter external labour cost item | D24: 0
A25: Enter external labour cost item | D25: 0
A26: Other Expenditure (eg equipment) | B26: Qty | C26: Rate | D26: Total Cost
A27: Enter expense type | D27: =B27*C27 -> 0
A28: Enter expense type | D28: =B28*C28 -> 0
A29: Enter expense type | D29: =B29*C29 -> 0
A30: Total External Expenses | E30: =SUM(D22:D29) -> 0
A31: Total Budget | E31: =SUM(E9:E30) -> 140
A33: M&V BUDGET AS A PROPORTION OF PROJECT COST/SAVINGS
A34: Project Savings / Implementation Cost | E34: $ | F34: M&V Percentage of Cost
A35: Estimated Annual Project Savings | E35: ='ECM Project Background'!C9 -> 0 | F35: =IFERROR(E31/E35,"")
A36: Estimated Implementation Cost | E36: ='ECM Project Background'!B10 -> 0 | F36: =IFERROR(E31/E36,"")

Sheet M&V Tasks
A1: MEASUREMENT AND VERIFICATION - TASK LIST
A2: PROJECT INFORMATION
A3: Project Name | B3: ='M&V Design'!B3 -> 0 | C3: Project # | J3: ='M&V Design'!D3 -> 0
A4: Project manager | B4: ='M&V Design'!B4 -> 0 | C4: Last Updated | J4: ='M&V Design'!D4 -> 0
A7: Resource | C7: ='M&V Budget'!A10 -> [Resource 1] | D7: ='M&V Budget'!A11 -> [Resource 2] | E7: ='M&V Budget'!A12 -> [Resource 3] | F7: ='M&V Budget'!A13 -> [Resource 4] | G7: ='M&V Budget'!A14 -> [Resource 5] | H7: ='M&V Budget'!A15 -> [Resource 6] | I7: Total | J7: Notes
A8: Total Hours | C8: =SUM(C10:C63) -> 1 | D8: =SUM(D10:D63) -> 0 | E8: =SUM(E10:E63) -> 0 | F8: =SUM(F10:F63) -> 0 | G8: =SUM(G10:G63) -> 0 | H8: =SUM(H10:H63) -> 0 | I8: =SUM(C8:H8) -> 1
A10: TASK LIST
B11: Project Management | I11: =SUM(I12:I17) -> 1 | J11: =I11/$I$8 -> 1
A12: 1 | B12: Initiate M&V project using internal processes | C12: 1 | I12: =SUM(C12:H12) -> 1
A13: 2 | B13: Obtain information regarding the ECM(s) to be implemented | I13: =SUM(C13:H13) -> 0
A14: 3 | B14: Establish M&V project team | I14: =SUM(C14:H14) -> 0
A15: 4 | B15: Develop preliminary budget estimate and evaluate cost/benefit | I15: =SUM(C15:H15) -> 0
A16: 5 | B16: Close out M&V project using internal processes | I16: =SUM(C16:H16) -> 0
A17: 6 | I17: =SUM(C17:H17) -> 0
B18: Develop M&V Plan | I18: =SUM(I19:I24) -> 0 | J18: =I18/$I$8 -> 0
A19: 1 | B19: Conduct a meeting with site contact, contractor and project manager to agree on approach | I19: =SUM(C19:H19) -> 0
A20: 2 | B20: Review project drawings to determine measurement boundary | I20: =SUM(C20:H20) -> 0
A21: 3 | B21: Review each ECM and decide on the appropriate M&V option, and key measurement parameter(s) | I21: =SUM(C21:H21) -> 0
A22: 4 | B22: Finalise M&V budget and timing | I22: =SUM(C22:H22) -> 0
A23: 5 | B23: Document agreed approach using standard M&V Plan proforma | I23: =SUM(C23:H23) -> 0
A24: 6 | I24: =SUM(C24:H24) -> 0
B25: Collect Baseline Data | I25: =SUM(I26:I31) -> 0 | J25: =I25/$I$8 -> 0
A26: 1 | B26: Prepare production data tracking sheet and discuss with equipment operator | I26: =SUM(C26:H26) -> 0 | J26: hard copy data entry sheet to be filled in by shift staff each hour
A27: 2 | B27: Hire electricity data logger | I27: =SUM(C27:H27) -> 0 | J27: energy data logger to be hired for 1 week
A28: 3 | B28: Install data logger on equipment and log for 1 week | I28: =SUM(C28:H28) -> 0 | J28: electrician to install and remove
A29: 4 | B29: Review throughput tracker to ensure quality data collection | I29: =SUM(C29:H29) -> 0 | J29: mid-week spot-check
A30: 5 | B30: Download logger data and check to ensure completeness | I30: =SUM(C30:H30) -> 0 | J30: use software supplied with logger to interrogate
A31: 6 | I31: =SUM(C31:H31) -> 0
B32: Implement ECM(s) | I32: =SUM(I33:I34) -> 0 | J32: =I32/$I$8 -> 0
A33: 1 | B33: Implement ECM, and establish steady-state operation | I33: =SUM(C33:H33) -> 0
A34: 2 | I34: =SUM(C34:H34) -> 0
B35: Collect Post-Retrofit Data | I35: =SUM(I36:I45) -> 0 | J35: =I35/$I$8 -> 0
A36: 1 | B36: Hire electricity data logger | J36: energy data logger to be hired for 1 week
A37: 2 | B37: Install data logger on equipment and log for 1 week | J37: electrician to install and remove
A38: 3 | B38: Review throughput tracker to ensure quality data collection | J38: mid-week spot-check
A39: 4 | B39: Download logger data and check to ensure completeness | J39: use software supplied with logger to interrogate
A40: 5 | I40: =SUM(C40:H40) -> 0
A41: 6 | I41: =SUM(C41:H41) -> 0
A42: 7 | I42: =SUM(C42:H42) -> 0
A43: 8 | I43: =SUM(C43:H43) -> 0
...

Sheet M&V Timing
A1: MEASUREMENT AND VERIFICATION - TIMING
A2: PROJECT INFORMATION
A3: Project Name | B3: ='M&V Design'!B3 -> 0 | C3: Project # | E3: ='M&V Design'!D3 -> 0
A4: Project manager | B4: ='M&V Design'!B4 -> 0 | C4: Last Updated | E4: ='M&V Design'!D4 -> 0
A7: Task list (linked to Tasks worksheet) | F7: Week Commencing
A8: Item | B8: Tasks | C8: Total Hours | D8: Plan Start | E8: Plan Finish | F8: =MIN(D:D)-MOD(MIN(D:D)-2,7) -> 41274 | K8: =F8+7 -> 41281 | P8: =K8+7 -> 41288 | U8: =P8+7 -> 41295 | Z8: =U8+7 -> 41302 | AE8: =Z8+7 -> 41309 | AJ8: =AE8+7 -> 41316 | AO8: =AJ8+7 -> 41323 | AT8: =AO8+7 -> 41330 | AY8: =AT8+7 -> 41337 | BD8: =AY8+7 -> 41344 | BI8: =BD8+7 -> 41351 | BN8: =BI8+7 -> 41358 | BS8: =BN8+7 -> 41365 | BX8: =BS8+7 -> 41372 | CC8: =BX8+7 -> 41379 | CH8: =CC8+7 -> 41386 | CM8: =CH8+7 -> 41393 | CR8: =CM8+7 -> 41400 | CW8: =CR8+7 -> 41407 | DB8: =CW8+7 -> 41414 | DG8: =DB8+7 -> 41421 | DL8: =DG8+7 -> 41428 | DQ8: =DL8+7 -> 41435 | DV8: =DQ8+7 -> 41442 | EA8: =DV8+7 -> 41449 | EF8: =EA8+7 -> 41456 | EK8: =EF8+7 -> 41463 | EP8: =EK8+7 -> 41470
D9: Enter Dates | F9: =F8 -> 41274 | G9: =F9+1 -> 41275 | H9: =G9+1 -> 41276 | I9: =H9+1 -> 41277 | J9: =I9+1 -> 41278 | K9: =F9+7 -> 41281 | L9: =K9+1 -> 41282 | M9: =L9+1 -> 41283 | N9: =M9+1 -> 41284 | O9: =N9+1 -> 41285 | P9: =K9+7 -> 41288 | Q9: =P9+1 -> 41289 | R9: =Q9+1 -> 41290 | S9: =R9+1 -> 41291 | T9: =S9+1 -> 41292 | U9: =P9+7 -> 41295 | V9: =U9+1 -> 41296 | W9: =V9+1 -> 41297 | X9: =W9+1 -> 41298 | Y9: =X9+1 -> 41299 | Z9: =U9+7 -> 41302 | AA9: =Z9+1 -> 41303 | AB9: =AA9+1 -> 41304 | AC9: =AB9+1 -> 41305 | AD9: =AC9+1 -> 41306 | AE9: =Z9+7 -> 41309 | AF9: =AE9+1 -> 41310 | AG9: =AF9+1 -> 41311 | AH9: =AG9+1 -> 41312 | AI9: =AH9+1 -> 41313 | AJ9: =AE9+7 -> 41316 | AK9: =AJ9+1 -> 41317 | AL9: =AK9+1 -> 41318 | AM9: =AL9+1 -> 41319 | AN9: =AM9+1 -> 41320 | AO9: =AJ9+7 -> 41323 | AP9: =AO9+1 -> 41324 | AQ9: =AP9+1 -> 41325 | AR9: =AQ9+1 -> 41326 | AS9: =AR9+1 -> 41327 | AT9: =AO9+7 -> 41330 | AU9: =AT9+1 -> 41331 | AV9: =AU9+1 -> 41332 | AW9: =AV9+1 -> 41333 | AX9: =AW9+1 -> 41334 | AY9: =AT9+7 -> 41337 | AZ9: =AY9+1 -> 41338 | BA9: =AZ9+1 -> 41339 | BB9: =BA9+1 -> 41340 | BC9: =BB9+1 -> 41341 | BD9: =AY9+7 -> 41344 | BE9: =BD9+1 -> 41345 | BF9: =BE9+1 -> 41346 | BG9: =BF9+1 -> 41347 | BH9: =BG9+1 -> 41348 | BI9: =BD9+7 -> 41351 | BJ9: =BI9+1 -> 41352 | BK9: =BJ9+1 -> 41353 | BL9: =BK9+1 -> 41354 | BM9: =BL9+1 -> 41355 | BN9: =BI9+7 -> 41358 | BO9: =BN9+1 -> 41359 | BP9: =BO9+1 -> 41360 | BQ9: =BP9+1 -> 41361 | BR9: =BQ9+1 -> 41362 | BS9: =BN9+7 -> 41365 | BT9: =BS9+1 -> 41366 | BU9: =BT9+1 -> 41367 | BV9: =BU9+1 -> 41368 | BW9: =BV9+1 -> 41369 | BX9: =BS9+7 -> 41372 | BY9: =BX9+1 -> 41373 | BZ9: =BY9+1 -> 41374 | CA9: =BZ9+1 -> 41375 | CB9: =CA9+1 -> 41376 | CC9: =BX9+7 -> 41379 | CD9: =CC9+1 -> 41380 | CE9: =CD9+1 -> 41381 | CF9: =CE9+1 -> 41382 | CG9: =CF9+1 -> 41383 | CH9: =CC9+7 -> 41386 | CI9: =CH9+1 -> 41387 | CJ9: =CI9+1 -> 41388 | CK9: =CJ9+1 -> 41389 | CL9: =CK9+1 -> 41390 | CM9: =CH9+7 -> 41393 | CN9: =CM9+1 -> 41394 | CO9: =CN9+1 -> 41395 | CP9: =CO9+1 -> 41396 | CQ9: =CP9+1 -> 41397 | CR9: =CM9+7 -> 41400 | CS9: =CR9+1 -> 41401 | CT9: =CS9+1 -> 41402 | CU9: =CT9+1 -> 41403 | CV9: =CU9+1 -> 41404 | CW9: =CR9+7 -> 41407 | CX9: =CW9+1 -> 41408 | CY9: =CX9+1 -> 41409 | CZ9: =CY9+1 -> 41410 | DA9: =CZ9+1 -> 41411 | DB9: =CW9+7 -> 41414 | DC9: =DB9+1 -> 41415 | DD9: =DC9+1 -> 41416 | DE9: =DD9+1 -> 41417 | DF9: =DE9+1 -> 41418 | DG9: =DB9+7 -> 41421 | DH9: =DG9+1 -> 41422 | DI9: =DH9+1 -> 41423 | DJ9: =DI9+1 -> 41424 | DK9: =DJ9+1 -> 41425 | DL9: =DG9+7 -> 41428 | DM9: =DL9+1 -> 41429 | DN9: =DM9+1 -> 41430 | DO9: =DN9+1 -> 41431 | DP9: =DO9+1 -> 41432 | DQ9: =DL9+7 -> 41435 | DR9: =DQ9+1 -> 41436 | DS9: =DR9+1 -> 41437 | DT9: =DS9+1 -> 41438 | DU9: =DT9+1 -> 41439 | DV9: =DQ9+7 -> 41442 | DW9: =DV9+1 -> 41443 | DX9: =DW9+1 -> 41444 | DY9: =DX9+1 -> 41445 | DZ9: =DY9+1 -> 41446 | EA9: =DV9+7 -> 41449 | EB9: =EA9+1 -> 41450 | EC9: =EB9+1 -> 41451 | ED9: =EC9+1 -> 41452 | EE9: =ED9+1 -> 41453 | EF9: =EA9+7 -> 41456 | EG9: =EF9+1 -> 41457 | EH9: =EG9+1 -> 41458 | EI9: =EH9+1 -> 41459 | EJ9: =EI9+1 -> 41460 | EK9: =EF9+7 -> 41463 | EL9: =EK9+1 -> 41464 | EM9: =EL9+1 -> 41465 | EN9: =EM9+1 -> 41466 | EO9: =EN9+1 -> 41467 | EP9: =EK9+7 -> 41470 | EQ9: =EP9+1 -> 41471 | ER9: =EQ9+1 -> 41472 | ES9: =ER9+1 -> 41473 | ET9: =ES9+1 -> 41474
A10: =TEXT('M&V Tasks'!A11,"#") | B10: =TEXT('M&V Tasks'!B11,"#") -> Project Management | C10: ='M&V Tasks'!I11 -> 1 | F10: =IF(AND(F$9>=$D10,F$9<=$E10),1,"") | G10: =IF(AND(G$9>=$D10,G$9<=$E10),1,"") | H10: =IF(AND(H$9>=$D10,H$9<=$E10),1,"") | I10: =IF(AND(I$9>=$D10,I$9<=$E10),1,"") | J10: =IF(AND(J$9>=$D10,J$9<=$E10),1,"") | K10: =IF(AND(K$9>=$D10,K$9<=$E10),1,"") | L10: =IF(AND(L$9>=$D10,L$9<=$E10),1,"") | M10: =IF(AND(M$9>=$D10,M$9<=$E10),1,"") | ... ET10: =IF(AND(ET$9>=$D10,ET$9<=$E10),1,"")
A11: =TEXT('M&V Tasks'!A12,"#") -> 1 | B11: =TEXT('M&V Tasks'!B12,"#") -> Initiate M&V project using internal processes | C11: ='M&V Tasks'!I12 -> 1 | D11: 41275 | F11: =IF(AND(F$9>=$D11,F$9<=$E11),1,"") | G11: =IF(AND(G$9>=$D11,G$9<=$E11),1,"") | H11: =IF(AND(H$9>=$D11,H$9<=$E11),1,"") | I11: =IF(AND(I$9>=$D11,I$9<=$E11),1,"") | J11: =IF(AND(J$9>=$D11,J$9<=$E11),1,"") | K11: =IF(AND(K$9>=$D11,K$9<=$E11),1,"") | L11: =IF(AND(L$9>=$D11,L$9<=$E11),1,"") | M11: =IF(AND(M$9>=$D11,M$9<=$E11),1,"") | ... ET11: =IF(AND(ET$9>=$D11,ET$9<=$E11),1,"")
A12: =TEXT('M&V Tasks'!A13,"#") -> 2 | B12: =TEXT('M&V Tasks'!B13,"#") -> Obtain information regarding the ECM(s) to be implemented | C12: ='M&V Tasks'!I13 -> 0 | F12: =IF(AND(F$9>=$D12,F$9<=$E12),1,"") | G12: =IF(AND(G$9>=$D12,G$9<=$E12),1,"") | H12: =IF(AND(H$9>=$D12,H$9<=$E12),1,"") | I12: =IF(AND(I$9>=$D12,I$9<=$E12),1,"") | J12: =IF(AND(J$9>=$D12,J$9<=$E12),1,"") | K12: =IF(AND(K$9>=$D12,K$9<=$E12),1,"") | L12: =IF(AND(L$9>=$D12,L$9<=$E12),1,"") | M12: =IF(AND(M$9>=$D12,M$9<=$E12),1,"") | ... ET12: =IF(AND(ET$9>=$D12,ET$9<=$E12),1,"")
A13: =TEXT('M&V Tasks'!A14,"#") -> 3 | B13: =TEXT('M&V Tasks'!B14,"#") -> Establish M&V project team | C13: ='M&V Tasks'!I14 -> 0 | F13: =IF(AND(F$9>=$D13,F$9<=$E13),1,"") | G13: =IF(AND(G$9>=$D13,G$9<=$E13),1,"") | H13: =IF(AND(H$9>=$D13,H$9<=$E13),1,"") | I13: =IF(AND(I$9>=$D13,I$9<=$E13),1,"") | J13: =IF(AND(J$9>=$D13,J$9<=$E13),1,"") | K13: =IF(AND(K$9>=$D13,K$9<=$E13),1,"") | L13: =IF(AND(L$9>=$D13,L$9<=$E13),1,"") | M13: =IF(AND(M$9>=$D13,M$9<=$E13),1,"") | ... ET13: =IF(AND(ET$9>=$D13,ET$9<=$E13),1,"")
A14: =TEXT('M&V Tasks'!A15,"#") -> 4 | B14: =TEXT('M&V Tasks'!B15,"#") -> Develop preliminary budget estimate and evaluate cost/benefit | C14: ='M&V Tasks'!I15 -> 0 | F14: =IF(AND(F$9>=$D14,F$9<=$E14),1,"") | G14: =IF(AND(G$9>=$D14,G$9<=$E14),1,"") | H14: =IF(AND(H$9>=$D14,H$9<=$E14),1,"") | I14: =IF(AND(I$9>=$D14,I$9<=$E14),1,"") | J14: =IF(AND(J$9>=$D14,J$9<=$E14),1,"") | K14: =IF(AND(K$9>=$D14,K$9<=$E14),1,"") | L14: =IF(AND(L$9>=$D14,L$9<=$E14),1,"") | M14: =IF(AND(M$9>=$D14,M$9<=$E14),1,"") | ... ET14: =IF(AND(ET$9>=$D14,ET$9<=$E14),1,"")
A15: =TEXT('M&V Tasks'!A16,"#") -> 5 | B15: =TEXT('M&V Tasks'!B16,"#") -> Close out M&V project using internal processes | C15: ='M&V Tasks'!I16 -> 0 | F15: =IF(AND(F$9>=$D15,F$9<=$E15),1,"") | G15: =IF(AND(G$9>=$D15,G$9<=$E15),1,"") | H15: =IF(AND(H$9>=$D15,H$9<=$E15),1,"") | I15: =IF(AND(I$9>=$D15,I$9<=$E15),1,"") | J15: =IF(AND(J$9>=$D15,J$9<=$E15),1,"") | K15: =IF(AND(K$9>=$D15,K$9<=$E15),1,"") | L15: =IF(AND(L$9>=$D15,L$9<=$E15),1,"") | M15: =IF(AND(M$9>=$D15,M$9<=$E15),1,"") | ... ET15: =IF(AND(ET$9>=$D15,ET$9<=$E15),1,"")
A16: =TEXT('M&V Tasks'!A17,"#") -> 6 | B16: =TEXT('M&V Tasks'!B17,"#") | C16: ='M&V Tasks'!I17 -> 0 | F16: =IF(AND(F$9>=$D16,F$9<=$E16),1,"") | G16: =IF(AND(G$9>=$D16,G$9<=$E16),1,"") | H16: =IF(AND(H$9>=$D16,H$9<=$E16),1,"") | I16: =IF(AND(I$9>=$D16,I$9<=$E16),1,"") | J16: =IF(AND(J$9>=$D16,J$9<=$E16),1,"") | K16: =IF(AND(K$9>=$D16,K$9<=$E16),1,"") | L16: =IF(AND(L$9>=$D16,L$9<=$E16),1,"") | M16: =IF(AND(M$9>=$D16,M$9<=$E16),1,"") | ... ET16: =IF(AND(ET$9>=$D16,ET$9<=$E16),1,"")
A17: =TEXT('M&V Tasks'!A18,"#") | B17: =TEXT('M&V Tasks'!B18,"#") -> Develop M&V Plan | C17: ='M&V Tasks'!I18 -> 0 | F17: =IF(AND(F$9>=$D17,F$9<=$E17),1,"") | G17: =IF(AND(G$9>=$D17,G$9<=$E17),1,"") | H17: =IF(AND(H$9>=$D17,H$9<=$E17),1,"") | I17: =IF(AND(I$9>=$D17,I$9<=$E17),1,"") | J17: =IF(AND(J$9>=$D17,J$9<=$E17),1,"") | K17: =IF(AND(K$9>=$D17,K$9<=$E17),1,"") | L17: =IF(AND(L$9>=$D17,L$9<=$E17),1,"") | M17: =IF(AND(M$9>=$D17,M$9<=$E17),1,"") | ... ET17: =IF(AND(ET$9>=$D17,ET$9<=$E17),1,"")
A18: =TEXT('M&V Tasks'!A19,"#") -> 1 | B18: =TEXT('M&V Tasks'!B19,"#") -> Conduct a meeting with site contact, contractor and project manager to agree on approach | C18: ='M&V Tasks'!I19 -> 0 | F18: =IF(AND(F$9>=$D18,F$9<=$E18),1,"") | G18: =IF(AND(G$9>=$D18,G$9<=$E18),1,"") | H18: =IF(AND(H$9>=$D18,H$9<=$E18),1,"") | I18: =IF(AND(I$9>=$D18,I$9<=$E18),1,"") | J18: =IF(AND(J$9>=$D18,J$9<=$E18),1,"") | K18: =IF(AND(K$9>=$D18,K$9<=$E18),1,"") | L18: =IF(AND(L$9>=$D18,L$9<=$E18),1,"") | M18: =IF(AND(M$9>=$D18,M$9<=$E18),1,"") | ... ET18: =IF(AND(ET$9>=$D18,ET$9<=$E18),1,"")
A19: =TEXT('M&V Tasks'!A20,"#") -> 2 | B19: =TEXT('M&V Tasks'!B20,"#") -> Review project drawings to determine measurement boundary | C19: ='M&V Tasks'!I20 -> 0 | F19: =IF(AND(F$9>=$D19,F$9<=$E19),1,"") | G19: =IF(AND(G$9>=$D19,G$9<=$E19),1,"") | H19: =IF(AND(H$9>=$D19,H$9<=$E19),1,"") | I19: =IF(AND(I$9>=$D19,I$9<=$E19),1,"") | J19: =IF(AND(J$9>=$D19,J$9<=$E19),1,"") | K19: =IF(AND(K$9>=$D19,K$9<=$E19),1,"") | L19: =IF(AND(L$9>=$D19,L$9<=$E19),1,"") | M19: =IF(AND(M$9>=$D19,M$9<=$E19),1,"") | ... ET19: =IF(AND(ET$9>=$D19,ET$9<=$E19),1,"")
A20: =TEXT('M&V Tasks'!A21,"#") -> 3 | B20: =TEXT('M&V Tasks'!B21,"#") -> Review each ECM and decide on the appropriate M&V option, and key measurement parameter(s) | C20: ='M&V Tasks'!I21 -> 0 | F20: =IF(AND(F$9>=$D20,F$9<=$E20),1,"") | G20: =IF(AND(G$9>=$D20,G$9<=$E20),1,"") | H20: =IF(AND(H$9>=$D20,H$9<=$E20),1,"") | I20: =IF(AND(I$9>=$D20,I$9<=$E20),1,"") | J20: =IF(AND(J$9>=$D20,J$9<=$E20),1,"") | K20: =IF(AND(K$9>=$D20,K$9<=$E20),1,"") | L20: =IF(AND(L$9>=$D20,L$9<=$E20),1,"") | M20: =IF(AND(M$9>=$D20,M$9<=$E20),1,"") | ... ET20: =IF(AND(ET$9>=$D20,ET$9<=$E20),1,"")
A21: =TEXT('M&V Tasks'!A22,"#") -> 4 | B21: =TEXT('M&V Tasks'!B22,"#") -> Finalise M&V budget and timing | C21: ='M&V Tasks'!I22 -> 0 | F21: =IF(AND(F$9>=$D21,F$9<=$E21),1,"") | G21: =IF(AND(G$9>=$D21,G$9<=$E21),1,"") | H21: =IF(AND(H$9>=$D21,H$9<=$E21),1,"") | I21: =IF(AND(I$9>=$D21,I$9<=$E21),1,"") | J21: =IF(AND(J$9>=$D21,J$9<=$E21),1,"") | K21: =IF(AND(K$9>=$D21,K$9<=$E21),1,"") | L21: =IF(AND(L$9>=$D21,L$9<=$E21),1,"") | M21: =IF(AND(M$9>=$D21,M$9<=$E21),1,"") | ... ET21: =IF(AND(ET$9>=$D21,ET$9<=$E21),1,"")
A22: =TEXT('M&V Tasks'!A23,"#") -> 5 | B22: =TEXT('M&V Tasks'!B23,"#") -> Document agreed approach using standard M&V Plan proforma | C22: ='M&V Tasks'!I23 -> 0 | F22: =IF(AND(F$9>=$D22,F$9<=$E22),1,"") | G22: =IF(AND(G$9>=$D22,G$9<=$E22),1,"") | H22: =IF(AND(H$9>=$D22,H$9<=$E22),1,"") | I22: =IF(AND(I$9>=$D22,I$9<=$E22),1,"") | J22: =IF(AND(J$9>=$D22,J$9<=$E22),1,"") | K22: =IF(AND(K$9>=$D22,K$9<=$E22),1,"") | L22: =IF(AND(L$9>=$D22,L$9<=$E22),1,"") | M22: =IF(AND(M$9>=$D22,M$9<=$E22),1,"") | ... ET22: =IF(AND(ET$9>=$D22,ET$9<=$E22),1,"")
A23: =TEXT('M&V Tasks'!A24,"#") -> 6 | B23: =TEXT('M&V Tasks'!B24,"#") | C23: ='M&V Tasks'!I24 -> 0 | F23: =IF(AND(F$9>=$D23,F$9<=$E23),1,"") | G23: =IF(AND(G$9>=$D23,G$9<=$E23),1,"") | H23: =IF(AND(H$9>=$D23,H$9<=$E23),1,"") | I23: =IF(AND(I$9>=$D23,I$9<=$E23),1,"") | J23: =IF(AND(J$9>=$D23,J$9<=$E23),1,"") | K23: =IF(AND(K$9>=$D23,K$9<=$E23),1,"") | L23: =IF(AND(L$9>=$D23,L$9<=$E23),1,"") | M23: =IF(AND(M$9>=$D23,M$9<=$E23),1,"") | ... ET23: =IF(AND(ET$9>=$D23,ET$9<=$E23),1,"")
... A65: =TEXT('M&V Tasks'!A66,"#") | B65: =TEXT('M&V Tasks'!B66,"#") | C65: ='M&V Tasks'!I66 -> 0 | F65: =IF(AND(F$9>=$D65,F$9<=$E65),1,"") | G65: =IF(AND(G$9>=$D65,G$9<=$E65),1,"") | H65: =IF(AND(H$9>=$D65,H$9<=$E65),1,"") | I65: =IF(AND(I$9>=$D65,I$9<=$E65),1,"") | J65: =IF(AND(J$9>=$D65,J$9<=$E65),1,"") | K65: =IF(AND(K$9>=$D65,K$9<=$E65),1,"") | L65: =IF(AND(L$9>=$D65,L$9<=$E65),1,"") | M65: =IF(AND(M$9>=$D65,M$9<=$E65),1,"") | ... ET65: =IF(AND(ET$9>=$D65,ET$9<=$E65),1,"")

Sheet M&V Results
A1: MEASUREMENT AND VERIFICATION - REPORTED OUTCOMES
A2: PROJECT INFORMATION
A3: Project Name | B3: ='M&V Design'!B3 -> 0 | E3: Project # | G3: ='M&V Design'!D3 -> 0
A4: Project manager | B4: ='M&V Design'!B4 -> 0 | E4: Last Updated | G4: ='M&V Design'!D4 -> 0
A7: PROJECT BENEFITS - SUMMARY
A8: Component | B8: Unit of Measure | C8: Adjusted Baseline | D8: Post-Retrofit | E8: Savings | F8: Savings % | G8: Precision % | H8: Confidence %
A9: Total Energy | B9: GJ | C9: =C16 -> 0 | D9: =D16 -> 0 | E9: =C9-D9 -> 0 | F9: =IFERROR(E9/C9,"") | G9: =G16 -> 0
A10: Demand | B10: kW | C10: =VLOOKUP(B10,B23:F24,2,FALSE) -> 0 | D10: =VLOOKUP(B10,B23:F24,3,FALSE) -> 0 | E10: =C10-D10 -> 0 | F10: =IFERROR(E10/C10,"") | G10: =VLOOKUP(B10,B23:H24,6,FALSE) -> 0
A11: Energy and Demand Cost ($) | B11: $ | C11: =C26 -> 0 | D11: =D26 -> 0 | E11: =C11-D11 -> 0 | F11: =IFERROR(E11/C11,"")
A12: Greenhouse Gas Emissions | B12: t. CO2-e | C12: =C34 -> 0 | D12: =D34 -> 0 | E12: =C12-D12 -> 0 | F12: =IFERROR(E12/C12,"")
A14: PROJECT BENEFITS - DETAILS
A15: Component | B15: Unit of Measure | C15: Adjusted Baseline | D15: Post-Retrofit | E15: Savings | F15: Savings % | G15: Precision % | H15: Confidence %
A16: Total Energy | B16: GJ | C16: =C17*3.6/1000+C18/1000 -> 0 | D16: =D17*3.6/1000+D18/1000 -> 0 | E16: =C16-D16 -> 0 | F16: =IFERROR(E16/C16,"") | G16: =G17 -> 0
A17: Electricity | B17: kWh | E17: =C17-D17 -> 0 | F17: =IFERROR(E17/C17,"")
A18: Natural Gas | B18: MJ | E18: =C18-D18 -> 0 | F18: =IFERROR(E18/C18,"")
A19: other | B19: tbc | F19: =IFERROR(E19/C19,"") | H19: =IFERROR(G19/E19,"")
A20: other | B20: tbc | F20: =IFERROR(E20/C20,"") | H20: =IFERROR(G20/E20,"")
A22: Demand
A23: Demand (kW) | B23: kW | E23: =C23-D23 -> 0 | F23: =IFERROR(E23/C23,"")
A24: Demand (kVA) | B24: kVA | E24: =C24-D24 -> 0 | F24: =IFERROR(E24/C24,"")
A26: Energy and Demand Cost ($) | B26: $ | C26: =SUM(C27:C32) -> 0 | D26: =SUM(D27:D32) -> 0 | E26: =C26-D26 -> 0 | F26: =IFERROR(E26/C26,"")
A27: Electricity | B27: $ | E27: =C27-D27 -> 0 | F27: =IFERROR(E27/C27,"")
A28: Natural Gas | B28: $ | E28: =C28-D28 -> 0 | F28: =IFERROR(E28/C28,"")
A29: =A19 -> other | B29: $ | E29: =C29-D29 -> 0 | F29: =IFERROR(E29/C29,"") | H29: =IFERROR(G29/E29,"")
A30: =A20 -> other | B30: $ | E30: =C30-D30 -> 0 | F30: =IFERROR(E30/C30,"") | H30: =IFERROR(G30/E30,"")
A31: Demand (kW) | B31: $ | E31: =C31-D31 -> 0 | F31: =IFERROR(E31/C31,"")
A32: Demand (kVA) | B32: $ | E32: =C32-D32 -> 0 | F32: =IFERROR(E32/C32,"")
A34: Greenhouse Gas Emissions | B34: t. CO2-e | C34: =SUM(C35:C38) -> 0 | D34: =SUM(D35:D38) -> 0 | E34: =SUM(E35:E38) -> 0 | F34: =IFERROR(E34/C34,"")
A35: Electricity | B35: t. CO2-e | C35: =C17*1.07/1000 -> 0 | D35: =D17*1.07/1000 -> 0 | E35: =C35-D35 -> 0 | F35: =IFERROR(E35/C35,"")
A36: Natural Gas | B36: t. CO2-e | C36: =C18*60/1000000 -> 0 | D36: =D18*60/1000000 -> 0 | E36: =C36-D36 -> 0 | F36: =IFERROR(E36/C36,"")
A37: =A19 -> other | B37: t. CO2-e | F37: =IFERROR(E37/C37,"") | G37: =IFERROR(F37/D37,"") | H37: =IFERROR(G37/E37,"")
A38: =A20 -> other | B38: t. CO2-e | F38: =IFERROR(E38/C38,"") | G38: =IFERROR(F38/D38,"") | H38: =IFERROR(G38/E38,"")
